<mujoco model="model_1">
    <worldbody>
        <geom type="plane" size="150 150 0.1" pos="0 0 -4" rgba=".5 .5 .9 1"/>
        <light name="top light" diffuse=".9 .5 .5" pos="0 0 10"/>

        <body pos="0 0 0" euler="0 0 0">
        <joint name="all" type="hinge" axis="0 0 1"/>
        <joint name="all2" type="slide" axis="0 0 0"/>
        <joint name="all2" type="slide" axis="0 1 0"/>

            <body name="telo_car" pos="0 0 2.5">
                <geom type="box" size="6 4 1" rgba="1 0.1 0.5 0.5"/>
            </body>
        
            <body name="left_one" pos="4 2.5 0" euler="90 0 0">
                <geom type="cylinder" size="1.5 0.5" rgba="0.2 0.2 0.8 1"/>
                <joint name="one_1" type="hinge" axis="0 1 0"/>
            </body>

            <body name="right_one" pos="4 -2.5 0" euler="90 0 0">
                <geom type="cylinder" size="1.5 0.5" rgba="0.2 0.2 0.8 1"/>
                <joint name="one_2" type="hinge" axis="0 1 0"/>
            </body>

            <body name="left_two" pos="-4 2.5 0" euler="90 0 0">
                <geom type="cylinder" size="1.5 0.5" rgba="0.2 0.2 0.8 1"/>
                <joint name="one_3" type="hinge" axis="0 1 0"/>
            </body>

            <body name="right_two" pos="-4 -2.5 0" euler="90 0 0">
                <geom type="cylinder" size="1.5 0.5" rgba="0.2 0.2 0.8 1"/>
                <joint name="one_4" type="hinge" axis="0 1 0"/>
            </body>


            
        </body>
    </worldbody>
</mujoco>